Workbook

Sheet FMX
H3: Курс евро | I3: 105
B5: FUNDERMAX
B7: ТИП ИЗДЕЛИЯ | C7: КУХОННАЯ СТОЛЕШНИЦА, СТЕНОВАЯ ПАНЕЛЬ/ФАРТУК и БОРТИК/ПЛИНТУС
B8: коллекция | C8: Interior NATURE & MATERIAL, FH/FH, черная сердцевина, 12 мм
B9: ДЕКОРЫ | C9: =IF(C8=ДАТ!B25,ДАТ!B26,IF(C8=ДАТ!C25,ДАТ!C26,IF(C8=ДАТ!D25,ДАТ!D26,IF(C8=ДАТ!E25,ДАТ!E26,IF(C8=ДАТ!F25,ДАТ!F26,IF(C8=ДАТ!G25,ДАТ!G26,ДАТ!G24)))))) -> 0599/0585/0581/0566/0565/0331/0260/0048
B11: № | C11: Длина детали, мм | D11: Ширина детали, мм | E11: Кол-во, шт | F11: Площадь, м2 | G11: Периметр, м.п. | H11: Стоимость, евро | I11: Стоимость, руб | K11: № | L11: Дополнительные услуги | O11: Ед. изм. | P11: Кол-во | Q11: Цена, руб/ед. | R11: Стоимость, руб.
B12: 1 | C12: 1000 | D12: 1000 | E12: 1 | F12: =IF(D12<=0,0,IF(C12<=0,0,IF(E12<=0,0,(D12*C12)*E12/1000000))) -> 1 | G12: =IF(D12<=0,0,IF(C12<=0,0,IF(E12<=0,0,(D12+C12)*2*E12/1000))) -> 4 | H12: =(ROUNDUP((IF(E12<=0,0,IF(ДАТ!I12=0,0,IF(ДАТ!J12=0,0,(E12*ДАТ!K12+G12*ДАТ!$N$25)))))*ДАТ!$O$25,0)*'Коэфф. фабрика'!$C$2*ДАТ!$O$26)*'Коэфф. салон'!C$3 -> 235 | I12: =ROUNDUP(H12*I3,0) -> 24675 | K12: 1 | L12: Обработка кромки по Тип-4 или Тип-5 | O12: п.м. | P12: 1 | Q12: =280*'Коэфф. фабрика'!C2 -> 280 | R12: =IF(P12<=0,0,P12*Q12) -> 280
B13: 2 | C13: 350 | D13: 50 | E13: 1 | F13: =IF(D13<=0,0,IF(C13<=0,0,IF(E13<=0,0,(D13*C13)*E13/1000000))) -> 0.0175 | G13: =IF(D13<=0,0,IF(C13<=0,0,IF(E13<=0,0,(D13+C13)*2*E13/1000))) -> 0.8 | H13: =(ROUNDUP((IF(E13<=0,0,IF(ДАТ!I13=0,0,IF(ДАТ!J13=0,0,(E13*ДАТ!K13+G13*ДАТ!$N$25)))))*ДАТ!$O$25,0)*'Коэфф. фабрика'!$C$2*ДАТ!$O$26)*'Коэфф. салон'!C$3 -> 17 | I13: =ROUNDUP(H13*I3,0) -> 1785 | K13: 2 | L13: Черновой край | O13: п.м. | P13: 1
B14: 3 | C14: 680 | D14: 610 | E14: 1 | F14: =IF(D14<=0,0,IF(C14<=0,0,IF(E14<=0,0,(D14*C14)*E14/1000000))) -> 0.4148 | G14: =IF(D14<=0,0,IF(C14<=0,0,IF(E14<=0,0,(D14+C14)*2*E14/1000))) -> 2.58 | H14: =(ROUNDUP((IF(E14<=0,0,IF(ДАТ!I14=0,0,IF(ДАТ!J14=0,0,(E14*ДАТ!K14+G14*ДАТ!$N$25)))))*ДАТ!$O$25,0)*'Коэфф. фабрика'!$C$2*ДАТ!$O$26)*'Коэфф. салон'!C$3 -> 78 | I14: =ROUNDUP(H14*I3,0) -> 8190 | K14: 3 | L14: Вырез под технику (накладная) | O14: шт. | P14: 1 | Q14: =2160*'Коэфф. фабрика'!C2 -> 2160 | R14: =IF(P14<=0,0,P14*Q14) -> 2160
B15: 4 | F15: =IF(D15<=0,0,IF(C15<=0,0,IF(E15<=0,0,(D15*C15)*E15/1000000))) -> 0 | G15: =IF(D15<=0,0,IF(C15<=0,0,IF(E15<=0,0,(D15+C15)*2*E15/1000))) -> 0 | H15: =(ROUNDUP((IF(E15<=0,0,IF(ДАТ!I15=0,0,IF(ДАТ!J15=0,0,(E15*ДАТ!K15+G15*ДАТ!$N$25)))))*ДАТ!$O$25,0)*'Коэфф. фабрика'!$C$2*ДАТ!$O$26)*'Коэфф. салон'!C$3 -> 0 | I15: =ROUNDUP(H15*I3,0) -> 0 | K15: 4 | L15: Вырез под технику (вровень/подклейка снизу) | O15: шт. | P15: 1 | Q15: 4030 | R15: =IF(P15<=0,0,P15*Q15) -> 4030
B16: 5 | F16: =IF(D16<=0,0,IF(C16<=0,0,IF(E16<=0,0,(D16*C16)*E16/1000000))) -> 0 | G16: =IF(D16<=0,0,IF(C16<=0,0,IF(E16<=0,0,(D16+C16)*2*E16/1000))) -> 0 | H16: =(ROUNDUP((IF(E16<=0,0,IF(ДАТ!I16=0,0,IF(ДАТ!J16=0,0,(E16*ДАТ!K16+G16*ДАТ!$N$25)))))*ДАТ!$O$25,0)*'Коэфф. фабрика'!$C$2*ДАТ!$O$26)*'Коэфф. салон'!C$3 -> 0 | I16: =ROUNDUP(H16*I3,0) -> 0 | K16: 5 | L16: Подклейка мойки к столешнице* | O16: шт. | P16: 1 | Q16: 5000 | R16: =IF(P16<=0,0,P16*Q16) -> 5000
B17: 6 | F17: =IF(D17<=0,0,IF(C17<=0,0,IF(E17<=0,0,(D17*C17)*E17/1000000))) -> 0 | G17: =IF(D17<=0,0,IF(C17<=0,0,IF(E17<=0,0,(D17+C17)*2*E17/1000))) -> 0 | H17: =(ROUNDUP((IF(E17<=0,0,IF(ДАТ!I17=0,0,IF(ДАТ!J17=0,0,(E17*ДАТ!K17+G17*ДАТ!$N$25)))))*ДАТ!$O$25,0)*'Коэфф. фабрика'!$C$2*ДАТ!$O$26)*'Коэфф. салон'!C$3 -> 0 | I17: =ROUNDUP(H17*I3,0) -> 0 | K17: 6 | L17: Встроенная мойка из HPL (424х374х17,5 мм) | O17: шт. | P17: 1 | Q17: 45000 | R17: =IF(P17<=0,0,P17*Q17) -> 45000
B18: 7 | F18: =IF(D18<=0,0,IF(C18<=0,0,IF(E18<=0,0,(D18*C18)*E18/1000000))) -> 0 | G18: =IF(D18<=0,0,IF(C18<=0,0,IF(E18<=0,0,(D18+C18)*2*E18/1000))) -> 0 | H18: =(ROUNDUP((IF(E18<=0,0,IF(ДАТ!I18=0,0,IF(ДАТ!J18=0,0,(E18*ДАТ!K18+G18*ДАТ!$N$25)))))*ДАТ!$O$25,0)*'Коэфф. фабрика'!$C$2*ДАТ!$O$26)*'Коэфф. салон'!C$3 -> 0 | I18: =ROUNDUP(H18*I3,0) -> 0 | K18: 7 | L18: Соединение столешниц (еврозапил или прямой стык)/K-TOP | O18: шт. | P18: 1 | Q18: =4200*'Коэфф. фабрика'!C2 -> 4200 | R18: =IF(P18<=0,0,P18*Q18) -> 4200
B19: 8 | F19: =IF(D19<=0,0,IF(C19<=0,0,IF(E19<=0,0,(D19*C19)*E19/1000000))) -> 0 | G19: =IF(D19<=0,0,IF(C19<=0,0,IF(E19<=0,0,(D19+C19)*2*E19/1000))) -> 0 | H19: =(ROUNDUP((IF(E19<=0,0,IF(ДАТ!I19=0,0,IF(ДАТ!J19=0,0,(E19*ДАТ!K19+G19*ДАТ!$N$25)))))*ДАТ!$O$25,0)*'Коэфф. фабрика'!$C$2*ДАТ!$O$26)*'Коэфф. салон'!C$3 -> 0 | I19: =ROUNDUP(H19*I3,0) -> 0 | K19: 8 | L19: Вырез отверстия Ø до 100 мм/присадка | O19: шт. | P19: 1 | Q19: =240*'Коэфф. фабрика'!C2 -> 240 | R19: =IF(P19<=0,0,P19*Q19) -> 240
B20: 9 | F20: =IF(D20<=0,0,IF(C20<=0,0,IF(E20<=0,0,(D20*C20)*E20/1000000))) -> 0 | G20: =IF(D20<=0,0,IF(C20<=0,0,IF(E20<=0,0,(D20+C20)*2*E20/1000))) -> 0 | H20: =(ROUNDUP((IF(E20<=0,0,IF(ДАТ!I20=0,0,IF(ДАТ!J20=0,0,(E20*ДАТ!K20+G20*ДАТ!$N$25)))))*ДАТ!$O$25,0)*'Коэфф. фабрика'!$C$2*ДАТ!$O$26)*'Коэфф. салон'!C$3 -> 0 | I20: =ROUNDUP(H20*I3,0) -> 0 | K20: 9 | L20: Вырез произвольной формы и размера | O20: п.м. | P20: 1 | Q20: =1600*'Коэфф. фабрика'!C2 -> 1600 | R20: =IF(P20<=0,0,P20*Q20) -> 1600
B21: 10 | F21: =IF(D21<=0,0,IF(C21<=0,0,IF(E21<=0,0,(D21*C21)*E21/1000000))) -> 0 | G21: =IF(D21<=0,0,IF(C21<=0,0,IF(E21<=0,0,(D21+C21)*2*E21/1000))) -> 0 | H21: =(ROUNDUP((IF(E21<=0,0,IF(ДАТ!I21=0,0,IF(ДАТ!J21=0,0,(E21*ДАТ!K21+G21*ДАТ!$N$25)))))*ДАТ!$O$25,0)*'Коэфф. фабрика'!$C$2*ДАТ!$O$26)*'Коэфф. салон'!C$3 -> 0 | I21: =ROUNDUP(H21*I3,0) -> 0 | K21: 10 | L21: Гравировка, фреза Ø 1мм | O21: п.м. | P21: 1 | Q21: =580*'Коэфф. фабрика'!C2 -> 580 | R21: =IF(P21<=0,0,P21*Q21) -> 580
B22: ИТОГО 1: | E22: =SUM(E12:E21) -> 3 | F22: =SUM(F12:F21) -> 1.4323 | G22: =SUM(G12:G21) -> 7.38 | H22: =SUM(H12:H21) -> 330 | I22: =SUM(I12:I21) -> 34650 | K22: 11 | L22: Установка мебельной муфты под винт М5, М6, М8 | O22: шт. | P22: 1 | Q22: =240*'Коэфф. фабрика'!C2 -> 240 | R22: =IF(P22<=0,0,P22*Q22) -> 240
K23: 12 | L23: Изготовление индивидуального паллета | O23: шт. | P23: 1 | Q23: =4200*'Коэфф. фабрика'!C2 -> 4200 | R23: =IF(P23<=0,0,P23*Q23) -> 4200
D24: - поля для введения параметров | K24: 13 | L24: Индивидуальная упаковка мягкая | O24: шт. | P24: 1 | Q24: =1200*'Коэфф. фабрика'!C2 -> 1200 | R24: =IF(P24<=0,0,P24*Q24) -> 1200
K25: 14 | L25: Усиленная упаковка | O25: шт. | P25: 1 | Q25: =2200*'Коэфф. фабрика'!C2 -> 2200 | R25: =IF(P25<=0,0,P25*Q25) -> 2200
K26: 15 | L26: Спец. упаковка жесткая | O26: шт. | P26: 1 | Q26: =4200*'Коэфф. фабрика'!C2 -> 4200 | R26: =IF(P26<=0,0,P26*Q26) -> 4200
K27: ИТОГО 2: | R27: =SUM(R12:R26)-P13*936 -> 74194
B28: Примечания: | K28: СКИДКА: | R28: 0
B29: *Подклейка осуществляется только тех моек, которые приобретаются вместе со столешницей. Клиентские мойки в работу не берутся. С ассортиментом моек и прочих кухонных аксессуаров можно ознакомиться на сайтах https://omoikiri.ru и https://florcom.ru. Наличие товара необходимо уточнять. | K29: ИТОГО 1+2 (со скидкой): | N29: =(I22+R27)*(1-R28) -> 108844
B30: 1. Стоимость приведена с НДС 20%;
B31: 2. В стоимость включена обработка деталей с кромкой Тип-1/Тип-2/Тип-3 + шлифовка;
B32: 3. Максимальный размер изделия по ширине – 1280 мм (для AP/RR, SX/IP, NW/NN) и 1830 мм (для FH/FH), по длине – 4080 мм;
B33: 4. Минимальный размер изделия по ширине – 50 мм, по длине – 150 мм;
B34: 5. Минимальный радиус скругления внутренних углов – 6 мм, минимальный радиус скругления внешних углов – ограничений нет;
B35: 6. Для коллекций Nature & Material и Enduro – направление рисунка декора вдоль Длины детали, для остальных коллекций – направление рисунка значения не имеет;
B36: 7. Соединения столешниц:
B37: - Прямой стык столешницы возможен только с фаской тип 1. Если с помощью прямого стыка необходимо нарастить длину, стык возможно изготовить как с фаской тип 1, так и без обработки (по запросу).
B38: - Еврозапил, по умолчанию, изготавливается без фаски, но возможно так же изготовление с фаской тип 1 (по запросу).
B39: 8. Внешние торцы изделий без обработки (без фаски) требуют аккуратного обращения при монтаже, поскольку данные торцы более подвержены образованию сколов.
B40: 9. Все изделия, у которых расстояние от края выреза до внешнего края столешницы менее 50 мм по умолчанию идут со спец. упаковкой
B41: Виды кромок:

Sheet ДАТ
B1: параметры, которые участвуют в формулах ниже | K1: параметры, которые участвуют в формулах ниже
D2: 680 | E2: 1360 | F2: 2040 | G2: 2720 | H2: 3400 | I2: 4080 | L2: Ширина, мм | N2: Длина, мм
B3: FH | C3: 610 | D3: =(C3*D2)/1000000 -> 0.4148 | E3: =(C3*E2)/1000000 -> 0.8296 | F3: =(C3*F2)/1000000 -> 1.2444 | G3: =(C3*G2)/1000000 -> 1.6592 | H3: =(C3*H2)/1000000 -> 2.074 | I3: =(C3*I2)/1000000 -> 2.4888 | L3: от | M3: до | N3: от | O3: до
C4: 1220 | D4: =(C4*D2)/1000000 -> 0.8296 | E4: =(C4*E2)/1000000 -> 1.6592 | F4: =(C4*F2)/1000000 -> 2.4888 | G4: =(C4*G2)/1000000 -> 3.3184 | H4: =(C4*H2)/1000000 -> 4.148 | I4: =(C4*I2)/1000000 -> 4.9776 | K4: КухСтол | L4: 450 | M4: 1854 | N4: 150 | O4: 4100
C5: 1830 | D5: =(C5*D2)/1000000 -> 1.2444 | E5: =(C5*E2)/1000000 -> 2.4888 | F5: =(C5*F2)/1000000 -> 3.7332 | G5: =(C5*G2)/1000000 -> 4.9776 | H5: =(C5*H2)/1000000 -> 6.222 | I5: =(C5*I2)/1000000 -> 7.4664 | K5: КухФас | L5: 150 | M5: 1000 | N5: 300 | O5: 1400
B6: FH/AP/SX/NN | C6: 640 | D6: =(C6*D2)/1000000 -> 0.4352 | E6: =(C6*E2)/1000000 -> 0.8704 | F6: =(C6*F2)/1000000 -> 1.3056 | G6: =(C6*G2)/1000000 -> 1.7408 | H6: =(C6*H2)/1000000 -> 2.176 | I6: =(C6*I2)/1000000 -> 2.6112 | K6: HoReCa | L6: 600 | M6: 1400 | N6: 600 | O6: 1400
C7: 1280 | D7: =(C7*D2)/1000000 -> 0.8704 | E7: =(C7*E2)/1000000 -> 1.7408 | F7: =(C7*F2)/1000000 -> 2.6112 | G7: =(C7*G2)/1000000 -> 3.4816 | H7: =(C7*H2)/1000000 -> 4.352 | I7: =(C7*I2)/1000000 -> 5.2224 | K7: Бортик | L7: 50 | M7: 150 | N7: 1360 | O7: 4100
B10: Interior FH/FH | I10: сводная по стоимости | P10: Aptico, Saxum, Enduro
B11: № | C11: Ширина, мм | D11: Длина, мм | E11: Площадь, м2 | F11: Периметр, м.п. | G11: Цена, евро/м2 | I11: м2 | J11: евро/м2 | K11: КухСтол, евро | L11: КухФас, евро | M11: HoReCa, евро | N11: Бортик, евро | P11: № | Q11: Ширина, мм | R11: Длина, мм | S11: Площадь, м2 | T11: Периметр, м.п. | U11: Цена, евро/м2
B12: 1 | C12: =IF(FMX!D12<$L$7,0,IF(FMX!D12<=$M$7,FMX!D12+50,IF(FMX!D12<=$C$6,650,IF(FMX!D12<=$C$7,1300,0)))) -> 1300 | D12: =IF(FMX!C12<N4,0,IF(FMX!C12<=D2,684,IF(FMX!C12<=E2,1368,IF(FMX!C12<=F2,2052,IF(FMX!C12<=G2,2736,IF(FMX!C12<=H2,3420,IF(FMX!C12<=I2,4100,0))))))) -> 1368 | E12: =(C12*D12)/1000000 -> 1.7784 | F12: =(C12+D12)*2/1000 -> 5.336 | G12: =IF(FMX!C8=B25,B28,IF(FMX!C8=C25,C28,IF(FMX!C8=D25,D28,IF(FMX!C8=E25,E28,IF(FMX!C8=F25,F28,IF(FMX!C8=G25,G28,0)))))) -> 104.64 | I12: =IF(FMX!C8=B25,S12,IF(FMX!C8=C25,E12,IF(FMX!C8=D25,E12,IF(FMX!C8=E25,S12,IF(FMX!C8=F25,S12,IF(FMX!C8=G25,S12,0)))))) -> 1.7784 | J12: =IF(FMX!C8=B25,U12,IF(FMX!C8=C25,G12,IF(FMX!C8=D25,G12,IF(FMX!C8=E25,G12,IF(FMX!C8=F25,U12,IF(FMX!C8=G25,U12,0)))))) -> 104.64 | K12: =I12*J12 -> 186.09178 | L12: =P35 -> 176 | M12: =P44 -> 188 | N12: =L53 -> 0 | P12: 1 | Q12: =IF(FMX!D12<L7,0,IF(FMX!D12<=M7,FMX!D12+50,IF(FMX!D12<=C6,650,IF(FMX!D12<=C7,1300,0)))) -> 1300 | R12: =IF(FMX!C12<N4,0,IF(FMX!C12<=D2,684,IF(FMX!C12<=E2,1368,IF(FMX!C12<=F2,2052,IF(FMX!C12<=G2,2736,IF(FMX!C12<=H2,3420,IF(FMX!C12<=I2,4100,0))))))) -> 1368 | S12: =(Q12*R12)/1000000 -> 1.7784 | T12: =(Q12+R12)*2/1000 -> 5.336 | U12: =IF(FMX!C8=B25,B28,IF(FMX!C8=C25,C28,IF(FMX!C8=D25,D28,IF(FMX!C8=E25,E28,IF(FMX!C8=F25,F28,IF(FMX!C8=G25,G28,0)))))) -> 104.64
B13: 2 | C13: =IF(FMX!D13<$L$7,0,IF(FMX!D13<=$M$7,FMX!D13+50,IF(FMX!D13<=$C$6,650,IF(FMX!D13<=$C$7,1300,0)))) -> 100 | D13: =IF(FMX!C13<N4,0,IF(FMX!C13<=D2,684,IF(FMX!C13<=E2,1368,IF(FMX!C13<=F2,2052,IF(FMX!C13<=G2,2736,IF(FMX!C13<=H2,3420,IF(FMX!C13<=I2,4100,0))))))) -> 684 | E13: =(C13*D13)/1000000 -> 0.0684 | F13: =(C13+D13)*2/1000 -> 1.568 | G13: =IF(FMX!C8=B25,B28,IF(FMX!C8=C25,C28,IF(FMX!C8=D25,D28,IF(FMX!C8=E25,E28,IF(FMX!C8=F25,F28,IF(FMX!C8=G25,G28,0)))))) -> 104.64 | I13: =IF(FMX!C8=B25,S13,IF(FMX!C8=C25,E13,IF(FMX!C8=D25,E13,IF(FMX!C8=E25,S13,IF(FMX!C8=F25,S13,IF(FMX!C8=G25,S13,0)))))) -> 0.0684 | J13: =IF(FMX!C8=B25,U13,IF(FMX!C8=C25,G13,IF(FMX!C8=D25,G13,IF(FMX!C8=E25,G13,IF(FMX!C8=F25,U13,IF(FMX!C8=G25,U13,0)))))) -> 104.64 | K13: =I13*J13 -> 7.157376 | L13: =P36 -> 0 | M13: =P45 -> 0 | N13: =L54 -> 41 | P13: 2 | Q13: =IF(FMX!D13<L7,0,IF(FMX!D13<=M7,FMX!D13+50,IF(FMX!D13<=C6,650,IF(FMX!D13<=C7,1300,0)))) -> 100 | R13: =IF(FMX!C13<N4,0,IF(FMX!C13<=D2,684,IF(FMX!C13<=E2,1368,IF(FMX!C13<=F2,2052,IF(FMX!C13<=G2,2736,IF(FMX!C13<=H2,3420,IF(FMX!C13<=I2,4100,0))))))) -> 684 | S13: =(Q13*R13)/1000000 -> 0.0684 | T13: =(Q13+R13)*2/1000 -> 1.568 | U13: =IF(FMX!C8=B25,B28,IF(FMX!C8=C25,C28,IF(FMX!C8=D25,D28,IF(FMX!C8=E25,E28,IF(FMX!C8=F25,F28,IF(FMX!C8=G25,G28,0)))))) -> 104.64
B14: 3 | C14: =IF(FMX!D14<$L$7,0,IF(FMX!D14<=$M$7,FMX!D14+50,IF(FMX!D14<=$C$6,650,IF(FMX!D14<=$C$7,1300,0)))) -> 650 | D14: =IF(FMX!C14<N4,0,IF(FMX!C14<=D2,684,IF(FMX!C14<=E2,1368,IF(FMX!C14<=F2,2052,IF(FMX!C14<=G2,2736,IF(FMX!C14<=H2,3420,IF(FMX!C14<=I2,4100,0))))))) -> 684 | E14: =(C14*D14)/1000000 -> 0.4446 | F14: =(C14+D14)*2/1000 -> 2.668 | G14: =IF(FMX!C8=B25,B28,IF(FMX!C8=C25,C28,IF(FMX!C8=D25,D28,IF(FMX!C8=E25,E28,IF(FMX!C8=F25,F28,IF(FMX!C8=G25,G28,0)))))) -> 104.64 | I14: =IF(FMX!C8=B25,S14,IF(FMX!C8=C25,E14,IF(FMX!C8=D25,E14,IF(FMX!C8=E25,S14,IF(FMX!C8=F25,S14,IF(FMX!C8=G25,S14,0)))))) -> 0.4446 | J14: =IF(FMX!C8=B25,U14,IF(FMX!C8=C25,G14,IF(FMX!C8=D25,G14,IF(FMX!C8=E25,G14,IF(FMX!C8=F25,U14,IF(FMX!C8=G25,U14,0)))))) -> 104.64 | K14: =I14*J14 -> 46.522944 | L14: =P37 -> 79 | M14: =P46 -> 87 | N14: =L55 -> 0 | P14: 3 | Q14: =IF(FMX!D14<L7,0,IF(FMX!D14<=M7,FMX!D14+50,IF(FMX!D14<=C6,650,IF(FMX!D14<=C7,1300,0)))) -> 650 | R14: =IF(FMX!C14<N4,0,IF(FMX!C14<=D2,684,IF(FMX!C14<=E2,1368,IF(FMX!C14<=F2,2052,IF(FMX!C14<=G2,2736,IF(FMX!C14<=H2,3420,IF(FMX!C14<=I2,4100,0))))))) -> 684 | S14: =(Q14*R14)/1000000 -> 0.4446 | T14: =(Q14+R14)*2/1000 -> 2.668 | U14: =IF(FMX!C8=B25,B28,IF(FMX!C8=C25,C28,IF(FMX!C8=D25,D28,IF(FMX!C8=E25,E28,IF(FMX!C8=F25,F28,IF(FMX!C8=G25,G28,0)))))) -> 104.64
B15: 4 | C15: =IF(FMX!D15<$L$7,0,IF(FMX!D15<=$M$7,FMX!D15+50,IF(FMX!D15<=$C$6,650,IF(FMX!D15<=$C$7,1300,0)))) -> 0 | D15: =IF(FMX!C15<N4,0,IF(FMX!C15<=D2,684,IF(FMX!C15<=E2,1368,IF(FMX!C15<=F2,2052,IF(FMX!C15<=G2,2736,IF(FMX!C15<=H2,3420,IF(FMX!C15<=I2,4100,0))))))) -> 0 | E15: =(C15*D15)/1000000 -> 0 | F15: =(C15+D15)*2/1000 -> 0 | G15: =IF(FMX!C8=B25,B28,IF(FMX!C8=C25,C28,IF(FMX!C8=D25,D28,IF(FMX!C8=E25,E28,IF(FMX!C8=F25,F28,IF(FMX!C8=G25,G28,0)))))) -> 104.64 | I15: =IF(FMX!C8=B25,S15,IF(FMX!C8=C25,E15,IF(FMX!C8=D25,E15,IF(FMX!C8=E25,S15,IF(FMX!C8=F25,S15,IF(FMX!C8=G25,S15,0)))))) -> 0 | J15: =IF(FMX!C8=B25,U15,IF(FMX!C8=C25,G15,IF(FMX!C8=D25,G15,IF(FMX!C8=E25,G15,IF(FMX!C8=F25,U15,IF(FMX!C8=G25,U15,0)))))) -> 104.64 | K15: =I15*J15 -> 0 | L15: =P38 -> 0 | M15: =P47 -> 0 | N15: =L56 -> 0 | P15: 4 | Q15: =IF(FMX!D15<L7,0,IF(FMX!D15<=M7,FMX!D15+50,IF(FMX!D15<=C6,650,IF(FMX!D15<=C7,1300,0)))) -> 0 | R15: =IF(FMX!C15<N4,0,IF(FMX!C15<=D2,684,IF(FMX!C15<=E2,1368,IF(FMX!C15<=F2,2052,IF(FMX!C15<=G2,2736,IF(FMX!C15<=H2,3420,IF(FMX!C15<=I2,4100,0))))))) -> 0 | S15: =(Q15*R15)/1000000 -> 0 | T15: =(Q15+R15)*2/1000 -> 0 | U15: =IF(FMX!C8=B25,B28,IF(FMX!C8=C25,C28,IF(FMX!C8=D25,D28,IF(FMX!C8=E25,E28,IF(FMX!C8=F25,F28,IF(FMX!C8=G25,G28,0)))))) -> 104.64
B16: 5 | C16: =IF(FMX!D16<$L$7,0,IF(FMX!D16<=$M$7,FMX!D16+50,IF(FMX!D16<=$C$6,650,IF(FMX!D16<=$C$7,1300,0)))) -> 0 | D16: =IF(FMX!C16<N4,0,IF(FMX!C16<=D2,684,IF(FMX!C16<=E2,1368,IF(FMX!C16<=F2,2052,IF(FMX!C16<=G2,2736,IF(FMX!C16<=H2,3420,IF(FMX!C16<=I2,4100,0))))))) -> 0 | E16: =(C16*D16)/1000000 -> 0 | F16: =(C16+D16)*2/1000 -> 0 | G16: =IF(FMX!C8=B25,B28,IF(FMX!C8=C25,C28,IF(FMX!C8=D25,D28,IF(FMX!C8=E25,E28,IF(FMX!C8=F25,F28,IF(FMX!C8=G25,G28,0)))))) -> 104.64 | I16: =IF(FMX!C8=B25,S16,IF(FMX!C8=C25,E16,IF(FMX!C8=D25,E16,IF(FMX!C8=E25,S16,IF(FMX!C8=F25,S16,IF(FMX!C8=G25,S16,0)))))) -> 0 | J16: =IF(FMX!C8=B25,U16,IF(FMX!C8=C25,G16,IF(FMX!C8=D25,G16,IF(FMX!C8=E25,G16,IF(FMX!C8=F25,U16,IF(FMX!C8=G25,U16,0)))))) -> 104.64 | K16: =I16*J16 -> 0 | L16: =P39 -> 0 | M16: =P48 -> 0 | N16: =L57 -> 0 | P16: 5 | Q16: =IF(FMX!D16<L7,0,IF(FMX!D16<=M7,FMX!D16+50,IF(FMX!D16<=C6,650,IF(FMX!D16<=C7,1300,0)))) -> 0 | R16: =IF(FMX!C16<N4,0,IF(FMX!C16<=D2,684,IF(FMX!C16<=E2,1368,IF(FMX!C16<=F2,2052,IF(FMX!C16<=G2,2736,IF(FMX!C16<=H2,3420,IF(FMX!C16<=I2,4100,0))))))) -> 0 | S16: =(Q16*R16)/1000000 -> 0 | T16: =(Q16+R16)*2/1000 -> 0 | U16: =IF(FMX!C8=B25,B28,IF(FMX!C8=C25,C28,IF(FMX!C8=D25,D28,IF(FMX!C8=E25,E28,IF(FMX!C8=F25,F28,IF(FMX!C8=G25,G28,0)))))) -> 104.64
B17: 6 | C17: =IF(FMX!D17<$L$7,0,IF(FMX!D17<=$M$7,FMX!D17+50,IF(FMX!D17<=$C$6,650,IF(FMX!D17<=$C$7,1300,0)))) -> 0 | D17: =IF(FMX!C17<N4,0,IF(FMX!C17<=D2,684,IF(FMX!C17<=E2,1368,IF(FMX!C17<=F2,2052,IF(FMX!C17<=G2,2736,IF(FMX!C17<=H2,3420,IF(FMX!C17<=I2,4100,0))))))) -> 0 | E17: =(C17*D17)/1000000 -> 0 | F17: =(C17+D17)*2/1000 -> 0 | G17: =IF(FMX!C8=B25,B28,IF(FMX!C8=C25,C28,IF(FMX!C8=D25,D28,IF(FMX!C8=E25,E28,IF(FMX!C8=F25,F28,IF(FMX!C8=G25,G28,0)))))) -> 104.64 | I17: =IF(FMX!C8=B25,S17,IF(FMX!C8=C25,E17,IF(FMX!C8=D25,E17,IF(FMX!C8=E25,S17,IF(FMX!C8=F25,S17,IF(FMX!C8=G25,S17,0)))))) -> 0 | J17: =IF(FMX!C8=B25,U17,IF(FMX!C8=C25,G17,IF(FMX!C8=D25,G17,IF(FMX!C8=E25,G17,IF(FMX!C8=F25,U17,IF(FMX!C8=G25,U17,0)))))) -> 104.64 | K17: =I17*J17 -> 0 | P17: 6 | Q17: =IF(FMX!D17<L7,0,IF(FMX!D17<=M7,FMX!D17+50,IF(FMX!D17<=C6,650,IF(FMX!D17<=C7,1300,0)))) -> 0 | R17: =IF(FMX!C17<N4,0,IF(FMX!C17<=D2,684,IF(FMX!C17<=E2,1368,IF(FMX!C17<=F2,2052,IF(FMX!C17<=G2,2736,IF(FMX!C17<=H2,3420,IF(FMX!C17<=I2,4100,0))))))) -> 0 | S17: =(Q17*R17)/1000000 -> 0 | T17: =(Q17+R17)*2/1000 -> 0 | U17: =IF(FMX!C8=B25,B28,IF(FMX!C8=C25,C28,IF(FMX!C8=D25,D28,IF(FMX!C8=E25,E28,IF(FMX!C8=F25,F28,IF(FMX!C8=G25,G28,0)))))) -> 104.64
B18: 7 | C18: =IF(FMX!D18<$L$7,0,IF(FMX!D18<=$M$7,FMX!D18+50,IF(FMX!D18<=$C$6,650,IF(FMX!D18<=$C$7,1300,0)))) -> 0 | D18: =IF(FMX!C18<N4,0,IF(FMX!C18<=D2,684,IF(FMX!C18<=E2,1368,IF(FMX!C18<=F2,2052,IF(FMX!C18<=G2,2736,IF(FMX!C18<=H2,3420,IF(FMX!C18<=I2,4100,0))))))) -> 0 | E18: =(C18*D18)/1000000 -> 0 | F18: =(C18+D18)*2/1000 -> 0 | G18: =IF(FMX!C8=B25,B28,IF(FMX!C8=C25,C28,IF(FMX!C8=D25,D28,IF(FMX!C8=E25,E28,IF(FMX!C8=F25,F28,IF(FMX!C8=G25,G28,0)))))) -> 104.64 | I18: =IF(FMX!C8=B25,S18,IF(FMX!C8=C25,E18,IF(FMX!C8=D25,E18,IF(FMX!C8=E25,S18,IF(FMX!C8=F25,S18,IF(FMX!C8=G25,S18,0)))))) -> 0 | J18: =IF(FMX!C8=B25,U18,IF(FMX!C8=C25,G18,IF(FMX!C8=D25,G18,IF(FMX!C8=E25,G18,IF(FMX!C8=F25,U18,IF(FMX!C8=G25,U18,0)))))) -> 104.64 | K18: =I18*J18 -> 0 | P18: 7 | Q18: =IF(FMX!D18<L7,0,IF(FMX!D18<=M7,FMX!D18+50,IF(FMX!D18<=C6,650,IF(FMX!D18<=C7,1300,0)))) -> 0 | R18: =IF(FMX!C18<N4,0,IF(FMX!C18<=D2,684,IF(FMX!C18<=E2,1368,IF(FMX!C18<=F2,2052,IF(FMX!C18<=G2,2736,IF(FMX!C18<=H2,3420,IF(FMX!C18<=I2,4100,0))))))) -> 0 | S18: =(Q18*R18)/1000000 -> 0 | T18: =(Q18+R18)*2/1000 -> 0 | U18: =IF(FMX!C8=B25,B28,IF(FMX!C8=C25,C28,IF(FMX!C8=D25,D28,IF(FMX!C8=E25,E28,IF(FMX!C8=F25,F28,IF(FMX!C8=G25,G28,0)))))) -> 104.64
B19: 8 | C19: =IF(FMX!D19<$L$7,0,IF(FMX!D19<=$M$7,FMX!D19+50,IF(FMX!D19<=$C$6,650,IF(FMX!D19<=$C$7,1300,0)))) -> 0 | D19: =IF(FMX!C19<N4,0,IF(FMX!C19<=D2,684,IF(FMX!C19<=E2,1368,IF(FMX!C19<=F2,2052,IF(FMX!C19<=G2,2736,IF(FMX!C19<=H2,3420,IF(FMX!C19<=I2,4100,0))))))) -> 0 | E19: =(C19*D19)/1000000 -> 0 | F19: =(C19+D19)*2/1000 -> 0 | G19: =IF(FMX!C8=B25,B28,IF(FMX!C8=C25,C28,IF(FMX!C8=D25,D28,IF(FMX!C8=E25,E28,IF(FMX!C8=F25,F28,IF(FMX!C8=G25,G28,0)))))) -> 104.64 | I19: =IF(FMX!C8=B25,S19,IF(FMX!C8=C25,E19,IF(FMX!C8=D25,E19,IF(FMX!C8=E25,S19,IF(FMX!C8=F25,S19,IF(FMX!C8=G25,S19,0)))))) -> 0 | J19: =IF(FMX!C8=B25,U19,IF(FMX!C8=C25,G19,IF(FMX!C8=D25,G19,IF(FMX!C8=E25,G19,IF(FMX!C8=F25,U19,IF(FMX!C8=G25,U19,0)))))) -> 104.64 | K19: =I19*J19 -> 0 | P19: 8 | Q19: =IF(FMX!D19<L7,0,IF(FMX!D19<=M7,FMX!D19+50,IF(FMX!D19<=C6,650,IF(FMX!D19<=C7,1300,0)))) -> 0 | R19: =IF(FMX!C19<N4,0,IF(FMX!C19<=D2,684,IF(FMX!C19<=E2,1368,IF(FMX!C19<=F2,2052,IF(FMX!C19<=G2,2736,IF(FMX!C19<=H2,3420,IF(FMX!C19<=I2,4100,0))))))) -> 0 | S19: =(Q19*R19)/1000000 -> 0 | T19: =(Q19+R19)*2/1000 -> 0 | U19: =IF(FMX!C8=B25,B28,IF(FMX!C8=C25,C28,IF(FMX!C8=D25,D28,IF(FMX!C8=E25,E28,IF(FMX!C8=F25,F28,IF(FMX!C8=G25,G28,0)))))) -> 104.64
B20: 9 | C20: =IF(FMX!D20<$L$7,0,IF(FMX!D20<=$M$7,FMX!D20+50,IF(FMX!D20<=$C$6,650,IF(FMX!D20<=$C$7,1300,0)))) -> 0 | D20: =IF(FMX!C20<N4,0,IF(FMX!C20<=D2,684,IF(FMX!C20<=E2,1368,IF(FMX!C20<=F2,2052,IF(FMX!C20<=G2,2736,IF(FMX!C20<=H2,3420,IF(FMX!C20<=I2,4100,0))))))) -> 0 | E20: =(C20*D20)/1000000 -> 0 | F20: =(C20+D20)*2/1000 -> 0 | G20: =IF(FMX!C8=B25,B28,IF(FMX!C8=C25,C28,IF(FMX!C8=D25,D28,IF(FMX!C8=E25,E28,IF(FMX!C8=F25,F28,IF(FMX!C8=G25,G28,0)))))) -> 104.64 | I20: =IF(FMX!C8=B25,S20,IF(FMX!C8=C25,E20,IF(FMX!C8=D25,E20,IF(FMX!C8=E25,S20,IF(FMX!C8=F25,S20,IF(FMX!C8=G25,S20,0)))))) -> 0 | J20: =IF(FMX!C8=B25,U20,IF(FMX!C8=C25,G20,IF(FMX!C8=D25,G20,IF(FMX!C8=E25,G20,IF(FMX!C8=F25,U20,IF(FMX!C8=G25,U20,0)))))) -> 104.64 | K20: =I20*J20 -> 0 | P20: 9 | Q20: =IF(FMX!D20<L7,0,IF(FMX!D20<=M7,FMX!D20+50,IF(FMX!D20<=C6,650,IF(FMX!D20<=C7,1300,0)))) -> 0 | R20: =IF(FMX!C20<N4,0,IF(FMX!C20<=D2,684,IF(FMX!C20<=E2,1368,IF(FMX!C20<=F2,2052,IF(FMX!C20<=G2,2736,IF(FMX!C20<=H2,3420,IF(FMX!C20<=I2,4100,0))))))) -> 0 | S20: =(Q20*R20)/1000000 -> 0 | T20: =(Q20+R20)*2/1000 -> 0 | U20: =IF(FMX!C8=B25,B28,IF(FMX!C8=C25,C28,IF(FMX!C8=D25,D28,IF(FMX!C8=E25,E28,IF(FMX!C8=F25,F28,IF(FMX!C8=G25,G28,0)))))) -> 104.64
B21: 10 | C21: =IF(FMX!D21<$L$7,0,IF(FMX!D21<=$M$7,FMX!D21+50,IF(FMX!D21<=$C$6,650,IF(FMX!D21<=$C$7,1300,0)))) -> 0 | D21: =IF(FMX!C21<N4,0,IF(FMX!C21<=D2,684,IF(FMX!C21<=E2,1368,IF(FMX!C21<=F2,2052,IF(FMX!C21<=G2,2736,IF(FMX!C21<=H2,3420,IF(FMX!C21<=I2,4100,0))))))) -> 0 | E21: =(C21*D21)/1000000 -> 0 | F21: =(C21+D21)*2/1000 -> 0 | G21: =IF(FMX!C8=B25,B28,IF(FMX!C8=C25,C28,IF(FMX!C8=D25,D28,IF(FMX!C8=E25,E28,IF(FMX!C8=F25,F28,IF(FMX!C8=G25,G28,0)))))) -> 104.64 | I21: =IF(FMX!C8=B25,S21,IF(FMX!C8=C25,E21,IF(FMX!C8=D25,E21,IF(FMX!C8=E25,S21,IF(FMX!C8=F25,S21,IF(FMX!C8=G25,S21,0)))))) -> 0 | J21: =IF(FMX!C8=B25,U21,IF(FMX!C8=C25,G21,IF(FMX!C8=D25,G21,IF(FMX!C8=E25,G21,IF(FMX!C8=F25,U21,IF(FMX!C8=G25,U21,0)))))) -> 104.64 | K21: =I21*J21 -> 0 | P21: 10 | Q21: =IF(FMX!D21<L7,0,IF(FMX!D21<=M7,FMX!D21+50,IF(FMX!D21<=C6,650,IF(FMX!D21<=C7,1300,0)))) -> 0 | R21: =IF(FMX!C21<N4,0,IF(FMX!C21<=D2,684,IF(FMX!C21<=E2,1368,IF(FMX!C21<=F2,2052,IF(FMX!C21<=G2,2736,IF(FMX!C21<=H2,3420,IF(FMX!C21<=I2,4100,0))))))) -> 0 | S21: =(Q21*R21)/1000000 -> 0 | T21: =(Q21+R21)*2/1000 -> 0 | U21: =IF(FMX!C8=B25,B28,IF(FMX!C8=C25,C28,IF(FMX!C8=D25,D28,IF(FMX!C8=E25,E28,IF(FMX!C8=F25,F28,IF(FMX!C8=G25,G28,0)))))) -> 104.64
B24: КУХОННАЯ СТОЛЕШНИЦА и ФАРТУК | C24: ПЛИНТУС и БОРТИК | G24: нет декоров | N24: Цена обработки для КухСтол, евро/м.п. | O24: Коэф.
B25: Interior APTICO, AP/RR, черная сердцевина, 12 мм | C25: Exterior ENDURO, NW/NN, черная сердцевина, 12 мм | D25: Interior COLOUR, FH/FH, черная сердцевина, 12 мм | E25: Interior NATURE & MATERIAL, FH/FH, черная сердцевина, 12 мм | F25: Interior SAXUM, SX/IP, черная сердцевина, 12 мм | N25: 12 | O25: 1
B26: 0606/0080/0077/0075/0018/0693 | C26: B794/B793/B428/0497/0427/0426/0421/0027/0026 | D26: 0085/0080/0077/0074/0851 | E26: 0599/0585/0581/0566/0565/0331/0260/0048 | F26: 0085/0080/0077 | N26: Наценка | O26: 1
B27: 1300 | C27: 1300 | D27: 1300 | E27: 1300 | F27: 1300
B28: 192 | C28: 159.36 | D28: 100.8 | E28: 104.64 | F28: 131.52 | G28: ОПТ - 20%
B29: цены за материал менять только тут, евро/м2
B30: ничего больше нигде не трогать!!!
B33: РАБОЧАЯ ТАБЛИЦА КухФас
B34: Коллекция | C34: Ширина, мм | D34: Длина, мм | E34: Площадь, м2 | F34: Периметр, м.п. | G34: Цена, евро/м2 | H34: Цена, евро/лист | I34: Ширина, мм | J34: Длина, мм | K34: Кол-во, шт/лист | L34: Площадь, м2 | M34: Периметр, м.п. | N34: Цена обработки, евро/м.п. | O34: Сумма обработки, евро | P34: Цена, евро/шт | Q34: прямой расчет
B35: =FMX!C8 -> Interior NATURE & MATERIAL, FH/FH, черная сердцевина, 12 мм | C35: =IF(FMX!C8=B25,B27,IF(FMX!C8=C25,C27,IF(FMX!C8=D25,D27,IF(FMX!C8=E25,E27,IF(FMX!C8=F25,F27,IF(FMX!C8=G25,G27,0)))))) -> 1300 | D35: 4100 | E35: =(C35*D35)/1000000 -> 5.33 | F35: =(C35+D35)*2/1000 -> 10.8 | G35: =IF(FMX!C8=B25,B28,IF(FMX!C8=C25,C28,IF(FMX!C8=D25,D28,IF(FMX!C8=E25,E28,IF(FMX!C8=F25,F28,IF(FMX!C8=G25,G28,0)))))) -> 104.64 | H35: =E35*G35 -> 557.7312 | I35: =IF(FMX!D12<L5,0,IF(FMX!D12<=M5,FMX!D12,0)) -> 1000 | J35: =IF(FMX!C12<N5,0,IF(FMX!C12<=O5,FMX!C12,0)) -> 1000 | K35: =IF(I35=0,0,IF(J35=0,0,(ROUNDDOWN(C35/(I35+6),0))*(ROUNDDOWN(D35/(J35+6),0)))) -> 4 | L35: =(I35*J35)*K35/1000000 -> 4 | M35: =(I35+J35)*2*K35/1000 -> 16 | N35: 9 | O35: =M35*N35 -> 144 | P35: =IF(I35=0,0,IF(J35=0,0,IF(K35=0,0,ROUNDUP((H35+O35)/K35,0)))) -> 176 | Q35: =IF(I35=0,0,IF(J35=0,0,ROUNDUP((G35*I35*J35/1000000)+(I35+J35)*2*N35/1000,0))) -> 141
C36: =IF(FMX!C8=B25,B27,IF(FMX!C8=C25,C27,IF(FMX!C8=D25,D27,IF(FMX!C8=E25,E27,IF(FMX!C8=F25,F27,IF(FMX!C8=G25,G27,0)))))) -> 1300 | D36: 4100 | E36: =(C36*D36)/1000000 -> 5.33 | F36: =(C36+D36)*2/1000 -> 10.8 | G36: =IF(FMX!C8=B25,B28,IF(FMX!C8=C25,C28,IF(FMX!C8=D25,D28,IF(FMX!C8=E25,E28,IF(FMX!C8=F25,F28,IF(FMX!C8=G25,G28,0)))))) -> 104.64 | H36: =E36*G36 -> 557.7312 | I36: =IF(FMX!D13<L5,0,IF(FMX!D13<=M5,FMX!D13,0)) -> 0 | J36: =IF(FMX!C13<N5,0,IF(FMX!C13<=O5,FMX!C13,0)) -> 350 | K36: =IF(I36=0,0,IF(J36=0,0,(ROUNDDOWN(C36/(I36+6),0))*(ROUNDDOWN(D36/(J36+6),0)))) -> 0 | L36: =(I36*J36)*K36/1000000 -> 0 | M36: =(I36+J36)*2*K36/1000 -> 0 | N36: 9 | O36: =M36*N36 -> 0 | P36: =IF(I36=0,0,IF(J36=0,0,IF(K36=0,0,ROUNDUP((H36+O36)/K36,0)))) -> 0 | Q36: =IF(I36=0,0,IF(J36=0,0,ROUNDUP((G36*I36*J36/1000000)+(I36+J36)*2*N36/1000,0))) -> 0
C37: =IF(FMX!C8=B25,B27,IF(FMX!C8=C25,C27,IF(FMX!C8=D25,D27,IF(FMX!C8=E25,E27,IF(FMX!C8=F25,F27,IF(FMX!C8=G25,G27,0)))))) -> 1300 | D37: 4100 | E37: =(C37*D37)/1000000 -> 5.33 | F37: =(C37+D37)*2/1000 -> 10.8 | G37: =IF(FMX!C8=B25,B28,IF(FMX!C8=C25,C28,IF(FMX!C8=D25,D28,IF(FMX!C8=E25,E28,IF(FMX!C8=F25,F28,IF(FMX!C8=G25,G28,0)))))) -> 104.64 | H37: =E37*G37 -> 557.7312 | I37: =IF(FMX!D14<L5,0,IF(FMX!D14<=M5,FMX!D14,0)) -> 610 | J37: =IF(FMX!C14<N5,0,IF(FMX!C14<=O5,FMX!C14,0)) -> 680 | K37: =IF(I37=0,0,IF(J37=0,0,(ROUNDDOWN(C37/(I37+6),0))*(ROUNDDOWN(D37/(J37+6),0)))) -> 10 | L37: =(I37*J37)*K37/1000000 -> 4.148 | M37: =(I37+J37)*2*K37/1000 -> 25.8 | N37: 9 | O37: =M37*N37 -> 232.2 | P37: =IF(I37=0,0,IF(J37=0,0,IF(K37=0,0,ROUNDUP((H37+O37)/K37,0)))) -> 79 | Q37: =IF(I37=0,0,IF(J37=0,0,ROUNDUP((G37*I37*J37/1000000)+(I37+J37)*2*N37/1000,0))) -> 67
C38: =IF(FMX!C8=B25,B27,IF(FMX!C8=C25,C27,IF(FMX!C8=D25,D27,IF(FMX!C8=E25,E27,IF(FMX!C8=F25,F27,IF(FMX!C8=G25,G27,0)))))) -> 1300 | D38: 4100 | E38: =(C38*D38)/1000000 -> 5.33 | F38: =(C38+D38)*2/1000 -> 10.8 | G38: =IF(FMX!C8=B25,B28,IF(FMX!C8=C25,C28,IF(FMX!C8=D25,D28,IF(FMX!C8=E25,E28,IF(FMX!C8=F25,F28,IF(FMX!C8=G25,G28,0)))))) -> 104.64 | H38: =E38*G38 -> 557.7312 | I38: =IF(FMX!D15<L5,0,IF(FMX!D15<=M5,FMX!D15,0)) -> 0 | J38: =IF(FMX!C15<N5,0,IF(FMX!C15<=O5,FMX!C15,0)) -> 0 | K38: =IF(I38=0,0,IF(J38=0,0,(ROUNDDOWN(C38/(I38+6),0))*(ROUNDDOWN(D38/(J38+6),0)))) -> 0 | L38: =(I38*J38)*K38/1000000 -> 0 | M38: =(I38+J38)*2*K38/1000 -> 0 | N38: 9 | O38: =M38*N38 -> 0 | P38: =IF(I38=0,0,IF(J38=0,0,IF(K38=0,0,ROUNDUP((H38+O38)/K38,0)))) -> 0 | Q38: =IF(I38=0,0,IF(J38=0,0,ROUNDUP((G38*I38*J38/1000000)+(I38+J38)*2*N38/1000,0))) -> 0
C39: =IF(FMX!C8=B25,B27,IF(FMX!C8=C25,C27,IF(FMX!C8=D25,D27,IF(FMX!C8=E25,E27,IF(FMX!C8=F25,F27,IF(FMX!C8=G25,G27,0)))))) -> 1300 | D39: 4100 | E39: =(C39*D39)/1000000 -> 5.33 | F39: =(C39+D39)*2/1000 -> 10.8 | G39: =IF(FMX!C8=B25,B28,IF(FMX!C8=C25,C28,IF(FMX!C8=D25,D28,IF(FMX!C8=E25,E28,IF(FMX!C8=F25,F28,IF(FMX!C8=G25,G28,0)))))) -> 104.64 | H39: =E39*G39 -> 557.7312 | I39: =IF(FMX!D16<L5,0,IF(FMX!D16<=M5,FMX!D16,0)) -> 0 | J39: =IF(FMX!C16<N5,0,IF(FMX!C16<=O5,FMX!C16,0)) -> 0 | K39: =IF(I39=0,0,IF(J39=0,0,(ROUNDDOWN(C39/(I39+6),0))*(ROUNDDOWN(D39/(J39+6),0)))) -> 0 | L39: =(I39*J39)*K39/1000000 -> 0 | M39: =(I39+J39)*2*K39/1000 -> 0 | N39: 9 | O39: =M39*N39 -> 0 | P39: =IF(I39=0,0,IF(J39=0,0,IF(K39=0,0,ROUNDUP((H39+O39)/K39,0)))) -> 0 | Q39: =IF(I39=0,0,IF(J39=0,0,ROUNDUP((G39*I39*J39/1000000)+(I39+J39)*2*N39/1000,0))) -> 0
B42: РАБОЧАЯ ТАБЛИЦА HoReCa
B43: Коллекция | C43: Ширина, мм | D43: Длина, мм | E43: Площадь, м2 | F43: Периметр, м.п. | G43: Цена, евро/м2 | H43: Цена, евро/лист | I43: Ширина, мм | J43: Длина, мм | K43: Кол-во, шт/лист | L43: Площадь, м2 | M43: Периметр, м.п. | N43: Цена обработки, евро/м.п. | O43: Сумма обработки, евро | P43: Цена, евро/шт | Q43: прямой расчет
B44: =FMX!C8 -> Interior NATURE & MATERIAL, FH/FH, черная сердцевина, 12 мм | C44: =IF(FMX!C8=B25,B27,IF(FMX!C8=C25,C27,IF(FMX!C8=D25,D27,IF(FMX!C8=E25,E27,IF(FMX!C8=F25,F27,IF(FMX!C8=G25,G27,0)))))) -> 1300 | D44: 4100 | E44: =(C44*D44)/1000000 -> 5.33 | F44: =(C44+D44)*2/1000 -> 10.8 | G44: =IF(FMX!C8=B25,B28,IF(FMX!C8=C25,C28,IF(FMX!C8=D25,D28,IF(FMX!C8=E25,E28,IF(FMX!C8=F25,F28,IF(FMX!C8=G25,G28,0)))))) -> 104.64 | H44: =E44*G44 -> 557.7312 | I44: =IF(FMX!D12<L6,0,IF(FMX!D12<=M6,FMX!D12,0)) -> 1000 | J44: =IF(FMX!C12<N6,0,IF(FMX!C12<=O6,FMX!C12,0)) -> 1000 | K44: =IF(I44=0,0,IF(J44=0,0,(ROUNDDOWN(C44/(I44+6),0))*(ROUNDDOWN(D44/(J44+6),0)))) -> 4 | L44: =(I44*J44)*K44/1000000 -> 4 | M44: =(I44+J44)*2*K44/1000 -> 16 | N44: 12 | O44: =M44*N44 -> 192 | P44: =IF(I44=0,0,IF(J44=0,0,IF(K44=0,0,ROUNDUP((H44+O44)/K44,0)))) -> 188 | Q44: =IF(I44=0,0,IF(J44=0,0,ROUNDUP((G44*I44*J44/1000000)+(I44+J44)*2*N44/1000,0))) -> 153
C45: =IF(FMX!C8=B25,B27,IF(FMX!C8=C25,C27,IF(FMX!C8=D25,D27,IF(FMX!C8=E25,E27,IF(FMX!C8=F25,F27,IF(FMX!C8=G25,G27,0)))))) -> 1300 | D45: 4100 | E45: =(C45*D45)/1000000 -> 5.33 | F45: =(C45+D45)*2/1000 -> 10.8 | G45: =IF(FMX!C8=B25,B28,IF(FMX!C8=C25,C28,IF(FMX!C8=D25,D28,IF(FMX!C8=E25,E28,IF(FMX!C8=F25,F28,IF(FMX!C8=G25,G28,0)))))) -> 104.64 | H45: =E45*G45 -> 557.7312 | I45: =IF(FMX!D13<L6,0,IF(FMX!D13<=M6,FMX!D13,0)) -> 0 | J45: =IF(FMX!C13<N6,0,IF(FMX!C13<=O6,FMX!C13,0)) -> 0 | K45: =IF(I45=0,0,IF(J45=0,0,(ROUNDDOWN(C45/(I45+6),0))*(ROUNDDOWN(D45/(J45+6),0)))) -> 0 | L45: =(I45*J45)*K45/1000000 -> 0 | M45: =(I45+J45)*2*K45/1000 -> 0 | N45: 12 | O45: =M45*N45 -> 0 | P45: =IF(I45=0,0,IF(J45=0,0,IF(K45=0,0,ROUNDUP((H45+O45)/K45,0)))) -> 0 | Q45: =IF(I45=0,0,IF(J45=0,0,ROUNDUP((G45*I45*J45/1000000)+(I45+J45)*2*N45/1000,0))) -> 0
C46: =IF(FMX!C8=B25,B27,IF(FMX!C8=C25,C27,IF(FMX!C8=D25,D27,IF(FMX!C8=E25,E27,IF(FMX!C8=F25,F27,IF(FMX!C8=G25,G27,0)))))) -> 1300 | D46: 4100 | E46: =(C46*D46)/1000000 -> 5.33 | F46: =(C46+D46)*2/1000 -> 10.8 | G46: =IF(FMX!C8=B25,B28,IF(FMX!C8=C25,C28,IF(FMX!C8=D25,D28,IF(FMX!C8=E25,E28,IF(FMX!C8=F25,F28,IF(FMX!C8=G25,G28,0)))))) -> 104.64 | H46: =E46*G46 -> 557.7312 | I46: =IF(FMX!D14<L6,0,IF(FMX!D14<=M6,FMX!D14,0)) -> 610 | J46: =IF(FMX!C14<N6,0,IF(FMX!C14<=O6,FMX!C14,0)) -> 680 | K46: =IF(I46=0,0,IF(J46=0,0,(ROUNDDOWN(C46/(I46+6),0))*(ROUNDDOWN(D46/(J46+6),0)))) -> 10 | L46: =(I46*J46)*K46/1000000 -> 4.148 | M46: =(I46+J46)*2*K46/1000 -> 25.8 | N46: 12 | O46: =M46*N46 -> 309.6 | P46: =IF(I46=0,0,IF(J46=0,0,IF(K46=0,0,ROUNDUP((H46+O46)/K46,0)))) -> 87 | Q46: =IF(I46=0,0,IF(J46=0,0,ROUNDUP((G46*I46*J46/1000000)+(I46+J46)*2*N46/1000,0))) -> 75
C47: =IF(FMX!C8=B25,B27,IF(FMX!C8=C25,C27,IF(FMX!C8=D25,D27,IF(FMX!C8=E25,E27,IF(FMX!C8=F25,F27,IF(FMX!C8=G25,G27,0)))))) -> 1300 | D47: 4100 | E47: =(C47*D47)/1000000 -> 5.33 | F47: =(C47+D47)*2/1000 -> 10.8 | G47: =IF(FMX!C8=B25,B28,IF(FMX!C8=C25,C28,IF(FMX!C8=D25,D28,IF(FMX!C8=E25,E28,IF(FMX!C8=F25,F28,IF(FMX!C8=G25,G28,0)))))) -> 104.64 | H47: =E47*G47 -> 557.7312 | I47: =IF(FMX!D15<L6,0,IF(FMX!D15<=M6,FMX!D15,0)) -> 0 | J47: =IF(FMX!C15<N6,0,IF(FMX!C15<=O6,FMX!C15,0)) -> 0 | K47: =IF(I47=0,0,IF(J47=0,0,(ROUNDDOWN(C47/(I47+6),0))*(ROUNDDOWN(D47/(J47+6),0)))) -> 0 | L47: =(I47*J47)*K47/1000000 -> 0 | M47: =(I47+J47)*2*K47/1000 -> 0 | N47: 12 | O47: =M47*N47 -> 0 | P47: =IF(I47=0,0,IF(J47=0,0,IF(K47=0,0,ROUNDUP((H47+O47)/K47,0)))) -> 0 | Q47: =IF(I47=0,0,IF(J47=0,0,ROUNDUP((G47*I47*J47/1000000)+(I47+J47)*2*N47/1000,0))) -> 0
C48: =IF(FMX!C8=B25,B27,IF(FMX!C8=C25,C27,IF(FMX!C8=D25,D27,IF(FMX!C8=E25,E27,IF(FMX!C8=F25,F27,IF(FMX!C8=G25,G27,0)))))) -> 1300 | D48: 4100 | E48: =(C48*D48)/1000000 -> 5.33 | F48: =(C48+D48)*2/1000 -> 10.8 | G48: =IF(FMX!C8=B25,B28,IF(FMX!C8=C25,C28,IF(FMX!C8=D25,D28,IF(FMX!C8=E25,E28,IF(FMX!C8=F25,F28,IF(FMX!C8=G25,G28,0)))))) -> 104.64 | H48: =E48*G48 -> 557.7312 | I48: =IF(FMX!D16<L6,0,IF(FMX!D16<=M6,FMX!D16,0)) -> 0 | J48: =IF(FMX!C16<N6,0,IF(FMX!C16<=O6,FMX!C16,0)) -> 0 | K48: =IF(I48=0,0,IF(J48=0,0,(ROUNDDOWN(C48/(I48+6),0))*(ROUNDDOWN(D48/(J48+6),0)))) -> 0 | L48: =(I48*J48)*K48/1000000 -> 0 | M48: =(I48+J48)*2*K48/1000 -> 0 | N48: 12 | O48: =M48*N48 -> 0 | P48: =IF(I48=0,0,IF(J48=0,0,IF(K48=0,0,ROUNDUP((H48+O48)/K48,0)))) -> 0 | Q48: =IF(I48=0,0,IF(J48=0,0,ROUNDUP((G48*I48*J48/1000000)+(I48+J48)*2*N48/1000,0))) -> 0
...

Sheet Коэфф. салон
B3: Введите коэфф. салон: | C3: 1

Sheet Коэфф. фабрика
B2: Введите коэфф. фабрика: | C2: 1
